Workbook

Sheet 1_Executive_Summary

Sheet Dashboard
A1: 2027 Key Metrics (Base Case)
A2: Total Forecast Revenue | B2: =Forecast_Model!D6 -> 5.6737682e+08 | X2: Years | Y2: 2023 | Z2: 2024 | AA2: 2025 | AB2: 2026 | AC2: 2027
A3: Gross Margin % | B3: =Forecast_Model!D14 -> 0.39782811 | X3: Total Revenue | Y3: =Historical_Analysis!B15 -> 4.3581778e+08 | Z3: =Historical_Analysis!B16 -> 4.6200103e+08 | AA3: =Historical_Analysis!B17 -> 4.8183654e+08 | AB3: =Forecast_Model!C6 -> 5.2280413e+08 | AC3: =Forecast_Model!D6 -> 5.6737682e+08
A4: EBIT | B4: =Forecast_Model!D21 -> 88082611 | X4: Gross margin % | Y4: =Historical_Analysis!G7 -> 0.38562215 | Z4: =Historical_Analysis!G8 -> 0.38917218 | AA4: =Historical_Analysis!G9 -> 0.38824151 | AB4: =Forecast_Model!C14 -> 0.39778584 | AC4: =Forecast_Model!D14 -> 0.39782811
A5: Net Income | B5: =Forecast_Model!D27 -> 62691907 | X5: Net Margin % | Y5: =Historical_Analysis!I7 -> 0.096302986 | Z5: =Historical_Analysis!I8 -> 0.098384831 | AA5: =Historical_Analysis!I9 -> 0.099131217 | AB5: =Forecast_Model!C28 -> 0.10883191 | AC5: =Forecast_Model!D28 -> 0.1104943
A6: Closing Cash | B6: =Forecast_Model!D44 -> 1.1490055e+08

Sheet Forecast_Model
A1: Line Items | B1: 2025-Actual | C1: 2026-Forecast | D1: 2027-Forecast
A2: Revenue
A3: Enterprise Revenue | B3: =Historical_Analysis!B35 -> 2.2806162e+08 | C3: =B3 * (1+ Assumptions!$B$3) -> 2.5086778e+08 | D3: =C3 * (1+ Assumptions!$B$3) -> 2.7595456e+08
A4: SMB Revenue | B4: =Historical_Analysis!B36 -> 1.4674686e+08 | C4: =B4 * (1+ Assumptions!$B$4) -> 1.5848661e+08 | D4: =C4 * (1+ Assumptions!$B$4) -> 1.7116553e+08
A5: Consumer Revenue | B5: =Historical_Analysis!B34 -> 1.0702807e+08 | C5: =B5 * (1+ Assumptions!$B$5) -> 1.1344975e+08 | D5: =C5 * (1+ Assumptions!$B$5) -> 1.2025674e+08
A6: Total Revenue | B6: =SUM(B3:B5) -> 4.8183654e+08 | C6: =SUM(C3:C5) -> 5.2280413e+08 | D6: =SUM(D3:D5) -> 5.6737682e+08
A7: COGS (Cost of Good Sold)
A8: Enterprise COGS | B8: =Historical_Analysis!C35 -> 1.4114704e+08 | C8: =C3 * Assumptions!$B$7 -> 1.5302934e+08 | D8: =D3 * Assumptions!$B$7 -> 1.6833228e+08
A9: SMB COGS | B9: =Historical_Analysis!C36 -> 85040729 | C9: =C4 * Assumptions!$B$8 -> 90337365 | D9: =D4 * Assumptions!$B$8 -> 97564354
A10: Consumer COGS | B10: =Historical_Analysis!C34 -> 68579822 | C10: =C5 * Assumptions!$B$9 -> 71473343 | D10: =D5 * Assumptions!$B$9 -> 75761743
A11: Total COGS | B11: =SUM(B8:B10) -> 2.9476759e+08 | C11: =SUM(C8:C10) -> 3.1484005e+08 | D11: =SUM(D8:D10) -> 3.4165838e+08
A12: Profitability
A13: Gross Profit | B13: =B6-B11 -> 1.8706895e+08 | C13: =C6-C11 -> 2.0796408e+08 | D13: =D6-D11 -> 2.2571845e+08
A14: Gross Margin | B14: =B13/B6 -> 0.38824151 | C14: =C13/C6 -> 0.39778584 | D14: =D13/D6 -> 0.39782811
A15: Operating Expenses (OpEx)
A16: Sales & Marketing | B16: =Historical_Analysis!C17 -> 52223664 | C16: =C6 * Assumptions!$B$11 -> 54894434 | D16: =D6 * Assumptions!$B$11 -> 59574567
A17: R&D | B17: =Historical_Analysis!D17 -> 26162660 | C17: =C6 * Assumptions!$B$12 -> 28754227 | D17: =D6 * Assumptions!$B$12 -> 31205725
A18: G&A | B18: =Historical_Analysis!E17 -> 30526446 | C18: =C6 * Assumptions!$B$13 -> 33982269 | D18: =D6 * Assumptions!$B$13 -> 36879494
A19: Depreciation | B19: =Historical_Analysis!F17 -> 9976051.8 | C19: =B19 -> 9976051.8 | D19: =C19 -> 9976051.8
A20: Total OpEx | B20: =SUM(B16:B19) -> 1.1888882e+08 | C20: =SUM(C16:C19) -> 1.2760698e+08 | D20: =SUM(D16:D19) -> 1.3763584e+08
A21: EBIT(Operating Profit) | B21: =B13-B20 -> 68180125 | C21: =C13-C20 -> 80357099 | D21: =D13-D20 -> 88082611
A22: EBIT Margin % | B22: =B21/B6 -> 0.14150053 | C22: =C21/C6 -> 0.15370402 | D22: =D21/D6 -> 0.15524535
A23: Interest & Tax
A24: Interest Expenses | B24: =Historical_Analysis!G17 -> 4493401.4 | C24: =B24 -> 4493401.4 | D24: =C24 -> 4493401.4
A25: EBT (Earning Before Tax) | B25: =B21-B24 -> 63686723 | C25: =C21-C24 -> 75863698 | D25: =D21-D24 -> 83589209
A26: Tax | B26: =B25*25% -> 15921681 | C26: =C25*25% -> 18965924 | D26: =D25*25% -> 20897302
A27: Net Income | B27: =B25-B26 -> 47765043 | C27: =C25-C26 -> 56897773 | D27: =D25-D26 -> 62691907
A28: Net Margin % | B28: =B27/B6 -> 0.099131217 | C28: =C27/C6 -> 0.10883191 | D28: =D27/D6 -> 0.1104943
A31: WORKING CAPITAL SCHEDULE
A32: Accounts Receivable (AR) | B32: =(B6/365) * Assumptions!$B$15 -> 55444204 | C32: =(C6/365) * Assumptions!$B$15 -> 60158284 | D32: =(D6/365) * Assumptions!$B$15 -> 65287196
A33: Inventory (INV) | B33: =(B11/365) * Assumptions!$B$16 -> 41994287 | C33: =(C11/365) * Assumptions!$B$16 -> 44853925 | D33: =(D11/365) * Assumptions!$B$16 -> 48674618
A34: Accounts Payable (AP) | B34: =(B11/365) * Assumptions!$B$17 -> 30688133 | C34: =(C11/365) * Assumptions!$B$17 -> 32777868 | D34: =(D11/365) * Assumptions!$B$17 -> 35569913
A35: Net Working Capital | B35: =B32+B33-B34 -> 66750359 | C35: =C32+C33-C34 -> 72234341 | D35: =D32+D33-D34 -> 78391901
A37: CASH FLOW STATEMENT
A38: Net Income | B38: =B27 -> 47765043 | C38: =C27 -> 56897773 | D38: =D27 -> 62691907
A39: (+) Depreciation | B39: =B19 -> 9976051.8 | C39: =C19 -> 9976051.8 | D39: =D19 -> 9976051.8
A40: (-) Change in net working Capital | B40: 0 | C40: =C35-B35 -> 5483981.9 | D40: =D35-C35 -> 6157560.5
A41: (-) Capital Expenditure(CapEx) | B41: =B6 * Assumptions!$B$19 -> 21682644 | C41: =C6 * Assumptions!$B$19 -> 23526186 | D41: =D6 * Assumptions!$B$19 -> 25531957
A42: Net Cash Flow | B42: =B38+B39-B40-B41 -> 36058450 | C42: =C38+C39-C40-C41 -> 37863657 | D42: =D38+D39-D40-D41 -> 40978441
A43: Opening Cash balance | B43: 0 | C43: =B44 -> 36058450 | D43: =C44 -> 73922107
...

Sheet Historical_Analysis
A5: Monthly / Yearly Data | F5: Margins & Growth %
A6: Years/Month | B6: Total Revenue | C6: Total Gross Profit | D6: Total EBIT | E6: Total Net Income | F6: Revenue Growth % | G6: Gross Margin% | H6: EBIT Margin % | I6: Net Margin %
A7: 2023 | B7: 4.3581778e+08 | C7: 1.6806099e+08 | D7: 60447263 | E7: 41970554 | F7: - | G7: =C7/B7 -> 0.38562215 | H7: =D7/B7 -> 0.13869848 | I7: =E7/B7 -> 0.096302986
A8: 2024 | B8: 4.6200103e+08 | C8: 1.7979795e+08 | D8: 65298388 | E8: 45453893 | F8: =B8/B7 -1 -> 0.060078432 | G8: =C8/B8 -> 0.38917218 | H8: =D8/B8 -> 0.14133819 | I8: =E8/B8 -> 0.098384831
A9: 2025 | B9: 4.8183654e+08 | C9: 1.8706895e+08 | D9: 68180125 | E9: 47765043 | F9: =B9/B8 -1 -> 0.04293391 | G9: =C9/B9 -> 0.38824151 | H9: =D9/B9 -> 0.14150053 | I9: =E9/B9 -> 0.099131217
A10: Grand Total | B10: 1.3796553e+09 | C10: 5.3492788e+08 | D10: 1.9392578e+08 | E10: 1.3518949e+08
A13: Expenses Structure | K13: Expenses % By Revenue
A14: Row Labels | B14: Total Revenue | C14: Total Sales_Marketing | D14: Total R&D | E14: Total G&A | F14: Total Depriciation | G14: Total Interest_Expense | H14: Total Tax | I14: Total CapEx | K14: S&M % | L14: R&D% | M14: G&A % | N14: Depriciation % | O14: Interest Expense %
A15: 2023 | B15: 4.3581778e+08 | C15: 45929689 | D15: 23137188 | E15: 28204625 | F15: 10342223 | G15: 4486524.3 | H15: 13990185 | I15: 18571863 | K15: =C15/B15 -> 0.10538737 | L15: =D15/B15 -> 0.053089132 | M15: =E15/B15 -> 0.064716554 | N15: =F15/B15 -> 0.023730614 | O15: =G15/B15 -> 0.010294496
A16: 2024 | B16: 4.6200103e+08 | C16: 48552249 | D16: 26527944 | E16: 29347405 | F16: 10071962 | G16: 4693196.9 | H16: 15151298 | I16: 21813767 | K16: =C16/B16 -> 0.10509122 | L16: =D16/B16 -> 0.057419665 | M16: =E16/B16 -> 0.063522381 | N16: =F16/B16 -> 0.021800736 | O16: =G16/B16 -> 0.010158412
A17: 2025 | B17: 4.8183654e+08 | C17: 52223664 | D17: 26162660 | E17: 30526446 | F17: 9976051.8 | G17: 4493401.4 | H17: 15921681 | I17: 20915895 | K17: =C17/B17 -> 0.10838461 | L17: =D17/B17 -> 0.054297792 | M17: =E17/B17 -> 0.063354362 | N17: =F17/B17 -> 0.020704224 | O17: =G17/B17 -> 0.0093255722
A18: Grand Total | B18: 1.3796553e+09 | C18: 1.467056e+08 | D18: 75827792 | E18: 88078477 | F18: 30390238 | G18: 13673123 | H18: 45063163 | I18: 61301526
A21: Revenue % By Segment | D21: Revenue % By Region | G21: Working Capital Efficiency
A22: Segment | B22: Revenue % | D22: Region | E22: Revenue % | G22: Years/Month | H22: Average of DSO | I22: Average of DIO | J22: Average of DPO
A23: Consumer | B23: 0.21634705 | D23: East | E23: 0.24852783 | G23: 2023 | H23: 41.596289 | I23: 53.690928 | J23: 37.400573
A24: Enterprise | B24: 0.48340183 | D24: North | E24: 0.25817938 | G24: 2024 | H24: 41.998799 | I24: 50.786211 | J24: 38.736037
A25: SMB | B25: 0.30025112 | D25: South | E25: 0.24147454 | G25: 2025 | H25: 42.239873 | I25: 52.567206 | J25: 37.428656
A26: Grand Total | B26: 1 | D26: West | E26: 0.25181825 | G26: Grand Total | H26: 41.944987 | I26: 52.348115 | J26: 37.855089
D27: Grand Total | E27: 1
A29: Revenue And COGS by Segment 2025
B30: Years
B31: 2025
A33: Segment | B33: Total Revenue | C33: Total COGS
A34: Consumer | B34: 1.0702807e+08 | C34: 68579822
A35: Enterprise | B35: 2.2806162e+08 | C35: 1.4114704e+08
A36: SMB | B36: 1.4674686e+08 | C36: 85040729
A37: Grand Total | B37: 4.8183654e+08 | C37: 2.9476759e+08

Sheet Historical_Operations
A1: Month | B1: Segment | C1: Region | D1: Units | E1: Avg_Price | F1: Revenue | G1: COGS
A2: 44927 | B2: Enterprise | C2: North | D2: 86 | E2: 41096.84 | F2: 3534328.2 | G2: 2132546.2
A3: 44927 | B3: Enterprise | C3: South | D3: 111 | E3: 41387.62 | F3: 4594026.2 | G3: 2904057.9
A4: 44927 | B4: Enterprise | C4: West | D4: 105 | E4: 42232.17 | F4: 4434378.3 | G4: 2682267.6
A5: 44927 | B5: Enterprise | C5: East | D5: 101 | E5: 43096.27 | F5: 4352723.2 | G5: 2685165.2
A6: 44927 | B6: SMB | C6: North | D6: 259 | E6: 14298.39 | F6: 3703283.9 | G6: 2176128.2
A7: 44927 | B7: SMB | C7: South | D7: 175 | E7: 14007.31 | F7: 2451279 | G7: 1432043
A8: 44927 | B8: SMB | C8: West | D8: 260 | E8: 14349.68 | F8: 3730917.6 | G8: 2043708
A9: 44927 | B9: SMB | C9: East | D9: 176 | E9: 14380 | F9: 2530879.7 | G9: 1504808.5
A10: 44927 | B10: Consumer | C10: North | D10: 227 | E10: 6140.01 | F10: 1393782.8 | G10: 890187.19
A11: 44927 | B11: Consumer | C11: South | D11: 298 | E11: 6210.83 | F11: 1850826.3 | G11: 1153149.5
A12: 44927 | B12: Consumer | C12: West | D12: 257 | E12: 6175.88 | F12: 1587200.4 | G12: 1077620.8
A13: 44927 | B13: Consumer | C13: East | D13: 308 | E13: 6017.8 | F13: 1853481.6 | G13: 1167664.1
... A433: 45992 | B433: Consumer | C433: East | D433: 341 | E433: 6022.65 | F433: 2053725 | G433: 1387832.3

Sheet Historical_Financials
A1: Month | B1: Revenue | C1: COGS | D1: Gross_Profit | E1: Sales_Marketing | F1: R&D | G1: G&A | H1: Depreciation | I1: EBIT | J1: Interest_Expense | K1: EBT | L1: Tax | M1: Net_Income | N1: DSO | O1: DIO | P1: DPO | Q1: Capex
A2: 44927 | B2: 36017107 | C2: 21849346 | D2: 14167761 | E2: 3790462.7 | F2: 1851599.1 | G2: 2199953.2 | H2: 862721.58 | I2: 5463024.4 | J2: 389999.84 | K2: 5073024.6 | L2: 1268256.1 | M2: 3804768.4 | N2: 37.122931 | O2: 55.14202 | P2: 41.235856 | Q2: 1325235.3
A3: 44958 | B3: 39308949 | C3: 24133072 | D3: 15175877 | E3: 3796547.2 | F3: 2031740.7 | G3: 2406443.4 | H3: 850161.01 | I3: 6090984.7 | J3: 363009.52 | K3: 5727975.2 | L3: 1431993.8 | M3: 4295981.4 | N3: 44.086324 | O3: 50.93183 | P3: 34.132766 | Q3: 1976201.5
A4: 44986 | B4: 37898176 | C4: 23741886 | D4: 14156289 | E4: 4495938.3 | F4: 1559362.8 | G4: 2596785.7 | H4: 878403.37 | I4: 4625798.9 | J4: 348051.72 | K4: 4277747.2 | L4: 1069436.8 | M4: 3208310.4 | N4: 43.558321 | O4: 53.085313 | P4: 37.432825 | Q4: 1667885.4
A5: 45017 | B5: 39037425 | C5: 24134759 | D5: 14902666 | E5: 3853519.6 | F5: 2016895.4 | G5: 2563329 | H5: 875998.17 | I5: 5592923.9 | J5: 336640.64 | K5: 5256283.3 | L5: 1314070.8 | M5: 3942212.4 | N5: 43.986232 | O5: 52.160137 | P5: 38.034878 | Q5: 1369838.8
A6: 45047 | B6: 34982232 | C6: 21281052 | D6: 13701180 | E6: 3503756.1 | F6: 2263391.1 | G6: 2126519.4 | H6: 830910.09 | I6: 4976603.6 | J6: 386209.47 | K6: 4590394.1 | L6: 1147598.5 | M6: 3442795.6 | N6: 42.651403 | O6: 51.21833 | P6: 37.969332 | Q6: 1519111.8
A7: 45078 | B7: 35426372 | C7: 21667057 | D7: 13759315 | E7: 3432337.5 | F7: 1794645.6 | G7: 2147033.8 | H7: 819826.98 | I7: 5565471 | J7: 404363.27 | K7: 5161107.8 | L7: 1290276.9 | M7: 3870830.8 | N7: 40.856488 | O7: 52.522812 | P7: 39.170501 | Q7: 1532190.7
A8: 45108 | B8: 39574189 | C8: 24524271 | D8: 15049917 | E8: 4617734.9 | F8: 2222424.8 | G8: 2781437.9 | H8: 848416.43 | I8: 4579903.4 | J8: 316597.91 | K8: 4263305.5 | L8: 1065826.4 | M8: 3197479.1 | N8: 43.461057 | O8: 52.327707 | P8: 37.028076 | Q8: 1509969.6
A9: 45139 | B9: 29701890 | C9: 18298479 | D9: 11403411 | E9: 2768314.1 | F9: 1533804.5 | G9: 1950627.3 | H9: 917623.56 | I9: 4233042 | J9: 363700.69 | K9: 3869341.3 | L9: 967335.32 | M9: 2902006 | N9: 40.262828 | O9: 56.587382 | P9: 33.760642 | Q9: 1366307.7
A10: 45170 | B10: 35187971 | C10: 21428769 | D10: 13759202 | E10: 3862413 | F10: 1898271.1 | G10: 2306944.5 | H10: 855206.84 | I10: 4836366.4 | J10: 414148.16 | K10: 4422218.3 | L10: 1105554.6 | M10: 3316663.7 | N10: 41.492509 | O10: 54.286602 | P10: 36.176101 | Q10: 1825771.4
A11: 45200 | B11: 34571534 | C11: 21302326 | D11: 13269207 | E11: 4124182 | F11: 2004113.9 | G11: 2197124.1 | H11: 865319.16 | I11: 4078468.4 | J11: 391949.41 | K11: 3686518.9 | L11: 921629.74 | M11: 2764889.2 | N11: 40.658756 | O11: 57.379104 | P11: 36.241622 | Q11: 1366563.3
A12: 45231 | B12: 39947959 | C12: 24452857 | D12: 15495102 | E12: 4239807 | F12: 2312231.5 | G12: 2690123.1 | H12: 817607.6 | I12: 5435332.6 | J12: 356369.82 | K12: 5078962.8 | L12: 1269740.7 | M12: 3809222.1 | N12: 40.601207 | O12: 54.609715 | P12: 39.284062 | Q12: 1751805.9
A13: 45261 | B13: 34163976 | C13: 20942917 | D13: 13221059 | E13: 3444676.6 | F13: 1648707 | G13: 2238303.3 | H13: 920028.51 | I13: 4969343.2 | J13: 415483.8 | K13: 4553859.4 | L13: 1138464.8 | M13: 3415394.5 | N13: 40.41741 | O13: 54.040186 | P13: 38.340217 | Q13: 1360981.8
... A37: 45992 | B37: 35566802 | C37: 21820730 | D37: 13746072 | E37: 4231296.8 | F37: 2070686 | G37: 2074447.1 | H37: 794724.81 | I37: 4574917.7 | J37: 356279.29 | K37: 4218638.4 | L37: 1054659.6 | M37: 3163978.8 | N37: 42.792622 | O37: 51.62067 | P37: 38.814789 | Q37: 1532667.5

Sheet Assumptions
A1: Assumptions Category | B1: Values | C1: Unit | D1: Base Case (1) | E1: Upside Case (2) | F1: Downside Case(3) | H1: Active Scenario -> | I1: 1
A2: 1. Revenue Assumptions
A3: Enterprise Revenue Growth | B3: =CHOOSE($I$1,D3,E3,F3) -> 0.1 | C3: % YoY | D3: 0.1 | E3: 0.15 | F3: 0.02
A4: SMB Revenue Growth | B4: =CHOOSE($I$1,D4,E4,F4) -> 0.08 | C4: % YoY | D4: 0.08 | E4: 0.12 | F4: 0.03
A5: Consumer Revenue Growth | B5: =CHOOSE($I$1,D5,E5,F5) -> 0.06 | C5: % YoY | D5: 0.06 | E5: 0.1 | F5: 0.01
A6: 2. COGS (Cost of goods sold)
A7: Enterprise COGS | B7: =CHOOSE($I$1,D7,E7,F7) -> 0.61 | C7: % of Segment Revenue | D7: 0.61 | E7: 0.58 | F7: 0.65
A8: SMB COGS | B8: =CHOOSE($I$1,D8,E8,F8) -> 0.57 | C8: % of Segment Revenue | D8: 0.57 | E8: 0.55 | F8: 0.6
A9: Consumer COGS | B9: =CHOOSE($I$1,D9,E9,F9) -> 0.63 | C9: % of Segment Revenue | D9: 0.63 | E9: 0.6 | F9: 0.68
A10: 3. Operating Expenses (OpEx)
A11: Sales & Marketing | B11: =CHOOSE($I$1,D11,E11,F11) -> 0.105 | C11: % of Total Revenue | D11: 0.105 | E11: 0.105 | F11: 0.105 | Y11: Enterprise | Z11: 0.236 | AA11: Total EBIT | AB11: 100000000
A12: R&D | B12: =CHOOSE($I$1,D12,E12,F12) -> 0.055 | C12: % of Total Revenue | D12: 0.055 | E12: 0.055 | F12: 0.055 | Y12: SMB Revenue Growth | Z12: 0.221 | AA12: Net Income | AB12: 70000000
A13: G&A | B13: =CHOOSE($I$1,D13,E13,F13) -> 0.065 | C13: % of Total Revenue | D13: 0.065 | E13: 0.065 | F13: 0.065 | Y13: enterprise cogs | Z13: 0.604 | AA13: Gross margin | AB13: 0.4
A14: 4. Working Capital
A15: DSO (Receivable) | B15: =CHOOSE($I$1,D15,E15,F15) -> 42 | C15: Days | D15: 42 | E15: 42 | F15: 42
A16: DIO (Inventory) | B16: =CHOOSE($I$1,D16,E16,F16) -> 52 | C16: Days | D16: 52 | E16: 52 | F16: 52
A17: DPO (Payable) | B17: =CHOOSE($I$1,D17,E17,F17) -> 38 | C17: Days | D17: 38 | E17: 38 | F17: 38
A18: 5. Other Financials
A19: Capex | B19: =CHOOSE($I$1,D19,E19,F19) -> 0.045 | C19: % of Total Revenue | D19: 0.045 | E19: 0.045 | F19: 0.045
A20: Tax Rate | B20: =CHOOSE($I$1,D20,E20,F20) -> 0.25 | C20: % | D20: 0.25 | E20: 0.25 | F20: 0.25
A21: Interest Expense (Annual) | B21: =CHOOSE($I$1,D21,E21,F21) -> 5000000 | C21: Currency | D21: 5000000 | E21: 5000000 | F21: 5000000
A22: Minimum Cash balance | B22: =CHOOSE($I$1,D22,E22,F22) -> 15000000 | C22: Currency | D22: 15000000 | E22: 15000000 | F22: 15000000

Sheet Scenarios
A1: Scenario | B1: Revenue Growth Adjustment | C1: COGS Adjustment | D1: Opex Adjustment
A2: Base Case | B2: 0 | C2: 0 | D2: 0
A3: Upside Case | B3: 0.05 | C3: -0.015 | D3: -0.005
A4: Downside Case | B4: -0.06 | C4: 0.02 | D4: 0.015

Sheet Forecast_Drivers
A1: Month | B1: Segment | C1: Revenue | D1: COGS
A2: 46023 | B2: Enterprise | C2: 21390567 | D2: 13048246
A3: 46023 | B3: SMB | C3: 13439949 | D3: 7660770.8
A4: 46023 | B4: Consumer | C4: 8936927.3 | D4: 5630264.2
A5: 46054 | B5: Enterprise | C5: 22770816 | D5: 13890198
A6: 46054 | B6: SMB | C6: 11806491 | D6: 6729700.1
A7: 46054 | B7: Consumer | C7: 10953973 | D7: 6901002.9
A8: 46082 | B8: Enterprise | C8: 21140565 | D8: 12895745
A9: 46082 | B9: SMB | C9: 15196193 | D9: 8661830.2
A10: 46082 | B10: Consumer | C10: 8736337.4 | D10: 5503892.6
A11: 46113 | B11: Enterprise | C11: 22100940 | D11: 13481573
A12: 46113 | B12: SMB | C12: 17394762 | D12: 9915014.6
A13: 46113 | B13: Consumer | C13: 10870177 | D13: 6848211.7
... A73: 46722 | B73: Consumer | C73: 8758820.9 | D73: 5518057.2
